Workbook

Sheet Director
A1: 2025 Year to Date
A2: AM | B2: (All)
A3: Text Code | B3: (All)
A4: Company | B4: (All)
A5: Vendor | B5: (All)
A7: Director | B7: Variance | C7: Booked | D7: As a % of Booked
A8: Owen Cunningham | B8: 145326.89 | C8: 12556381 | D8: 0.0028160455
A9: Olivia Gorfain | B9: 78196.72 | C9: 16189253 | D9: 0.0019016387
A10: Norma Lopez | B10: 49175.93 | C10: 6933299.7 | D10: 0.0036749827
A11: Jill Marsh | B11: 48648.31 | C11: 5820005.6 | D11: 0.0063324304
A12: Lela Huenergardt | B12: 42378.55 | C12: 3648805.2 | D12: 0.0063121541
A13: Simon Sheppard | B13: 36991.48 | C13: 837514.92 | D13: 0.033716141
A14: Kate Ingelstrom | B14: 33362.16 | C14: 2470161 | D14: 0.014841832
A15: Chris Cicisly | B15: 31118.41 | C15: 6857499.4 | D15: 0.0036014806
A16: Nick Christianson | B16: 21374.35 | C16: 960059.98 | D16: 0.053008469
A17: Mark Dailey | B17: 16795.47 | C17: 1674828.1 | D17: 0.018921085
A18: Z-Stephanie Hawkins | B18: 12330.58 | C18: 0 | D18: 0
A19: Troy Ocariza | B19: 12155.24 | C19: 863078.52 | D19: 0.024708044
... A33: Paul Razo | B33: 128.31 | C33: 288491.56 | D33: 0.044476171
A34: Torrey Carroll | B34: 100 | C34: #N/A | D34: 0
A35: Z-Denelle Bourgeois | B35: 90 | C35: 0 | D35: 0
A36: Frankie Kim | B36: 10 | C36: #N/A | D36: 0
A37: Grand Total | B37: 566154.8 | C37: #N/A | D37: 0

Sheet Account Manager
A1: 2025 Year to Date
A2: Salesperson | B2: (All)
A3: Text Code | B3: (All)
A4: Company | B4: (All)
A5: Vendor | B5: (All)
A7: AM | B7: Variance
A8: Carina Collison | B8: 51773.7
A9: Lindsay Hanief | B9: 51286.99
A10: Josie Maitlen,Torrey Crell | B10: 40812.91
A11: Norma Lopez | B11: 38798.67
A12: Patty Medina | B12: 37094.89
A13: Kimi Katsuyoshi | B13: 30792.11
A14: Farrah Race | B14: 30149.74
A15: Frances Kim | B15: 28344.4
A16: Megan Ewers | B16: 26218.37
A17: Jenni Lombardi | B17: 22502.13
A18: Genesis Rita | B18: 21685.02
A19: Mary Sparacino | B19: 19011.43
... A88: Anthony Pantaleoni,Melissa Rokes | B88: -218.55
B89: -219.4
A90: Intuit-OR 205 | B90: -219.4
A91: 93472 | B91: -219.4
A92: addt shipping charges to get the fabric sooner | B92: 63.98
A93: Credit Line Added to Match Acknowledgement | B93: -283.38
A94: Saoirse O'Connor | B94: -557.31
A95: Casey Fleming,Norma Lopez | B95: -908
A96: Andrea Greever | B96: -2852.54
A97: Chryslyn Perkins | B97: -4623.57
A98: Grand Total | B98: 566154.8

Sheet Type
A1: 2025 Year to Date
A2: Salesperson | B2: (All)
A3: AM | B3: (All)
A4: Company | B4: (All)
A5: Customer | B5: (All)
A6: Vendor | B6: (All)
A8: Error Type | B8: Variance
A9: Specification Error | B9: 253067.95
A10: Miscellaneous | B10: 127976.01
A11: Customer Accomodation | B11: 115818.83
A12: Shipping Charges | B12: 36880.75
A13: Vendor Caused | B13: 32411.26
A14: Grand Total | B14: 566154.8

Sheet Office
A1: 2025 Year to Date
A2: Office | B2: Variance
A3: San Francisco | B3: 323716.74
A4: San Jose | B4: 190525.05
A5: Sacramento | B5: 51913.01
A6: Grand Total | B6: 566154.8

Sheet Top 10 Vendors
A1: 2025 Year to Date
A2: Vendor | B2: Variance
A3: SERVICE - Service West- San Leandro | B3: 65517.56
A4: KNO - Knoll, Inc. | B4: 62470.09
A5: HMI - Herman Miller | B5: 57915.22
A6: ADRIANI - Adrian Inc. - Stations San Jose | B6: 21363.92
A7: ABSFACI - ABS Facility Services, Inc. | B7: 16237.48
A8: ALLMODU - Allmodular Systems, Inc. | B8: 14213.76
A9: TBD - TBD | B9: 13710.25
A10: ARD - Arcadia | B10: 12464.63
A11: COMMERC04 - Commercial Interiors West, Inc. | B11: 12114.2
A12: GEI - Geiger International, Inc. | B12: 11094.1
A13: Grand Total | B13: 287101.21

Sheet Top 10 Clients
A1: 2025 Year to Date
A2: Client | B2: Variance | C2: As a % of Booked
A3: Samuel Merritt University | B3: 54265.42 | C3: 0.046058879
A4: Intuit-OR 205 | B4: 42046.21 | C4: 0.0051613126
A5: Levi Strauss & Co | B5: 31376.33 | C5: 0.12245429
A6: Altos Labs, Inc. | B6: 23627.85 | C6: 0.039655072
A7: Sequoia Capital Operations, LLC | B7: 22031.39 | C7: 0.0079424929
A8: Davis Polk & Wardwell LLP | B8: 20314.9 | C8: 0.14636696
A9: Orrick, Herrington & Sutcliffe LLP | B9: 16675.42 | C9: 0.0095515881
A10: Stanford University | B10: 15194.74 | C10: 0.0087950207
A11: Peregrine Technologies, Inc. | B11: 14906.75 | C11: 0.35905325
A12: San Francisco State University | B12: 13461.99 | C12: 0
A13: Grand Total | B13: 253901 | C13: 0.015291271

Sheet Data
A1: Line Item Text Listing
A2: Order | B2: Line # | C2: Salesperson | D2: Customer | E2: Product ID | F2: Product Description | G2: OPC | H2: Line Item Text Code | I2: Line Item Text Code Description | J2: Company | K2: Vendor | L2: QTY | M2: Ext. Sell | N2: Ext. Cost | O2: Misc. Code | P2: Text Code | Q2: Profit Loss | R2: Bookings | S2: Client Bookings | T2: AM
A3: 73180 | B3: 283 | C3: Mark Dailey | D3: NetApp | E3: WAREHOUSE STORAGE | F3: Warehouse Storage Nov For fibre chairs, stools & side chairs | G3: STORE | H3: MISC | I3: Storage | J3: San Jose | K3: SERVICE - Service West- San Leandro | L3: 1 | M3: 0 | N3: 264.6 | O3: Shanna Dollarhide | P3: =VLOOKUP(Table1[[#This Row],[Line Item Text Code]],$U$3:$V$7,2,FALSE) -> Miscellaneous | Q3: =Table1[[#This Row],[Ext. Cost]]-Table1[[#This Row],[Ext. Sell]] -> 264.6 | R3: =VLOOKUP(C3,Bookings!$A$1:$B$33,2,FALSE) -> 1917863.2 | S3: =IFERROR(VLOOKUP(D3,Bookings!E:F,2,FALSE),0) -> 0 | T3: =IFERROR(VLOOKUP(Table1[[#This Row],[Order]],Bookings_with_AM_Report!A:L,12,FALSE),"N/A") -> Norma Lopez | U3: MISC | V3: Miscellaneous
A4: 73180 | B4: 284 | C4: Mark Dailey | D4: NetApp | E4: WAREHOUSE STORAGE | F4: Warehouse Storage Jan For fibre chairs, stools & side chairs | G4: STORE | H4: MISC | I4: Storage | J4: San Jose | K4: SERVICE - Service West- San Leandro | L4: 1 | M4: 0 | N4: 264.6 | O4: Shanna Dollarhide | P4: =VLOOKUP(Table1[[#This Row],[Line Item Text Code]],$U$3:$V$7,2,FALSE) -> Miscellaneous | Q4: =Table1[[#This Row],[Ext. Cost]]-Table1[[#This Row],[Ext. Sell]] -> 264.6 | R4: =VLOOKUP(C4,Bookings!$A$1:$B$33,2,FALSE) -> 1917863.2 | S4: =IFERROR(VLOOKUP(D4,Bookings!E:F,2,FALSE),0) -> 0 | T4: =IFERROR(VLOOKUP(Table1[[#This Row],[Order]],Bookings_with_AM_Report!A:L,12,FALSE),"N/A") -> Norma Lopez | U4: CUST | V4: Customer Accomodation
A5: 73180 | B5: 285 | C5: Mark Dailey | D5: NetApp | E5: WAREHOUSE STORAGE | F5: Warehouse Storage Feb For fibre chairs, stools & side chairs | G5: STORE | H5: MISC | I5: Storage | J5: San Jose | K5: SERVICE - Service West- San Leandro | L5: 1 | M5: 0 | N5: 264.6 | O5: Shanna Dollarhide | P5: =VLOOKUP(Table1[[#This Row],[Line Item Text Code]],$U$3:$V$7,2,FALSE) -> Miscellaneous | Q5: =Table1[[#This Row],[Ext. Cost]]-Table1[[#This Row],[Ext. Sell]] -> 264.6 | R5: =VLOOKUP(C5,Bookings!$A$1:$B$33,2,FALSE) -> 1917863.2 | S5: =IFERROR(VLOOKUP(D5,Bookings!E:F,2,FALSE),0) -> 0 | T5: =IFERROR(VLOOKUP(Table1[[#This Row],[Order]],Bookings_with_AM_Report!A:L,12,FALSE),"N/A") -> Norma Lopez | U5: SHIP | V5: Shipping Charges
A6: 73180 | B6: 286 | C6: Mark Dailey | D6: NetApp | E6: WAREHOUSE STORAGE | F6: Warehouse Storage March For fibre chairs, stools & side chairs | G6: STORE | H6: MISC | I6: Storage | J6: San Jose | K6: SERVICE - Service West- San Leandro | L6: 1 | M6: 0 | N6: 264.6 | O6: Shanna Dollarhide | P6: =VLOOKUP(Table1[[#This Row],[Line Item Text Code]],$U$3:$V$7,2,FALSE) -> Miscellaneous | Q6: =Table1[[#This Row],[Ext. Cost]]-Table1[[#This Row],[Ext. Sell]] -> 264.6 | R6: =VLOOKUP(C6,Bookings!$A$1:$B$33,2,FALSE) -> 1917863.2 | S6: =IFERROR(VLOOKUP(D6,Bookings!E:F,2,FALSE),0) -> 0 | T6: =IFERROR(VLOOKUP(Table1[[#This Row],[Order]],Bookings_with_AM_Report!A:L,12,FALSE),"N/A") -> Norma Lopez | U6: SPEC | V6: Specification Error
A7: 73180 | B7: 287 | C7: Mark Dailey | D7: NetApp | E7: WAREHOUSE STORAGE | F7: Warehouse Storage April For fibre chairs, stools & side chairs | G7: STORE | H7: MISC | I7: Storage | J7: San Jose | K7: SERVICE - Service West- San Leandro | L7: 1 | M7: 0 | N7: 264.6 | O7: Shanna Dollarhide | P7: =VLOOKUP(Table1[[#This Row],[Line Item Text Code]],$U$3:$V$7,2,FALSE) -> Miscellaneous | Q7: =Table1[[#This Row],[Ext. Cost]]-Table1[[#This Row],[Ext. Sell]] -> 264.6 | R7: =VLOOKUP(C7,Bookings!$A$1:$B$33,2,FALSE) -> 1917863.2 | S7: =IFERROR(VLOOKUP(D7,Bookings!E:F,2,FALSE),0) -> 0 | T7: =IFERROR(VLOOKUP(Table1[[#This Row],[Order]],Bookings_with_AM_Report!A:L,12,FALSE),"N/A") -> Norma Lopez | U7: VEN | V7: Vendor Caused
A8: 73180 | B8: 288 | C8: Mark Dailey | D8: NetApp | E8: WAREHOUSE STORAGE | F8: Warehouse Storage May For fibre chairs, stools & side chairs | G8: STORE | H8: MISC | I8: Storage | J8: San Jose | K8: SERVICE - Service West- San Leandro | L8: 1 | M8: 0 | N8: 264.6 | O8: Shanna Dollarhide | P8: =VLOOKUP(Table1[[#This Row],[Line Item Text Code]],$U$3:$V$7,2,FALSE) -> Miscellaneous | Q8: =Table1[[#This Row],[Ext. Cost]]-Table1[[#This Row],[Ext. Sell]] -> 264.6 | R8: =VLOOKUP(C8,Bookings!$A$1:$B$33,2,FALSE) -> 1917863.2 | S8: =IFERROR(VLOOKUP(D8,Bookings!E:F,2,FALSE),0) -> 0 | T8: =IFERROR(VLOOKUP(Table1[[#This Row],[Order]],Bookings_with_AM_Report!A:L,12,FALSE),"N/A") -> Norma Lopez
A9: 73180 | B9: 289 | C9: Mark Dailey | D9: NetApp | E9: WAREHOUSE STORAGE | F9: Warehouse Storage June For fibre chairs, stools & side chairs | G9: STORE | H9: MISC | I9: Storage | J9: San Jose | K9: SERVICE - Service West- San Leandro | L9: 1 | M9: 0 | N9: 264.6 | O9: Shanna Dollarhide | P9: =VLOOKUP(Table1[[#This Row],[Line Item Text Code]],$U$3:$V$7,2,FALSE) -> Miscellaneous | Q9: =Table1[[#This Row],[Ext. Cost]]-Table1[[#This Row],[Ext. Sell]] -> 264.6 | R9: =VLOOKUP(C9,Bookings!$A$1:$B$33,2,FALSE) -> 1917863.2 | S9: =IFERROR(VLOOKUP(D9,Bookings!E:F,2,FALSE),0) -> 0 | T9: =IFERROR(VLOOKUP(Table1[[#This Row],[Order]],Bookings_with_AM_Report!A:L,12,FALSE),"N/A") -> Norma Lopez
A10: 73180 | B10: 290 | C10: Mark Dailey | D10: NetApp | E10: WAREHOUSE STORAGE | F10: Warehouse Storage July For fibre chairs, stools & side chairs | G10: STORE | H10: MISC | I10: Storage | J10: San Jose | K10: SERVICE - Service West- San Leandro | L10: 1 | M10: 0 | N10: 264.6 | O10: Shanna Dollarhide | P10: =VLOOKUP(Table1[[#This Row],[Line Item Text Code]],$U$3:$V$7,2,FALSE) -> Miscellaneous | Q10: =Table1[[#This Row],[Ext. Cost]]-Table1[[#This Row],[Ext. Sell]] -> 264.6 | R10: =VLOOKUP(C10,Bookings!$A$1:$B$33,2,FALSE) -> 1917863.2 | S10: =IFERROR(VLOOKUP(D10,Bookings!E:F,2,FALSE),0) -> 0 | T10: =IFERROR(VLOOKUP(Table1[[#This Row],[Order]],Bookings_with_AM_Report!A:L,12,FALSE),"N/A") -> Norma Lopez
A11: 78772 | B11: 179 | C11: Jill Marsh | D11: Folger Levin | E11: Rebill-Oustanding balace | F11: Remaining balance due for invoice 5213711 | G11: PRO | H11: MISC | I11: Inv 5213711 was partially paid leaving the balance of $577.00 Past Due. | J11: San Francisco | K11: KNO - Knoll, Inc. | L11: 1 | M11: 0 | N11: 577 | O11: Nicole Lentini | P11: =VLOOKUP(Table1[[#This Row],[Line Item Text Code]],$U$3:$V$7,2,FALSE) -> Miscellaneous | Q11: =Table1[[#This Row],[Ext. Cost]]-Table1[[#This Row],[Ext. Sell]] -> 577 | R11: =VLOOKUP(C11,Bookings!$A$1:$B$33,2,FALSE) -> 6210075.2 | S11: =IFERROR(VLOOKUP(D11,Bookings!E:F,2,FALSE),0) -> 0 | T11: =IFERROR(VLOOKUP(Table1[[#This Row],[Order]],Bookings_with_AM_Report!A:L,12,FALSE),"N/A") -> Patty Medina
A12: 80461 | B12: 123 | C12: Lela Huenergardt | D12: County of Santa Clara | E12: FABRICATION | F12: Price to go to site during normal business hours, drill & install (2) new lock assemblies for a storage cabinet already at site. All hardware will be provided by KBM. Does not include any permits. | G12: FABR | H12: CUST | I12: adjusting the locks for the client. | J12: San Jose | K12: ALLMODU - Allmodular Systems, Inc. | L12: 1 | M12: 0 | N12: 845 | O12: Marlene Dyson | P12: =VLOOKUP(Table1[[#This Row],[Line Item Text Code]],$U$3:$V$7,2,FALSE) -> Customer Accomodation | Q12: =Table1[[#This Row],[Ext. Cost]]-Table1[[#This Row],[Ext. Sell]] -> 845 | R12: =VLOOKUP(C12,Bookings!$A$1:$B$33,2,FALSE) -> 3879926.5 | S12: =IFERROR(VLOOKUP(D12,Bookings!E:F,2,FALSE),0) -> 435136.95 | T12: =IFERROR(VLOOKUP(Table1[[#This Row],[Order]],Bookings_with_AM_Report!A:L,12,FALSE),"N/A") -> Megan Ewers
A13: 80461 | B13: 124 | C13: Lela Huenergardt | D13: County of Santa Clara | E13: FABRICATION | F13: Return Trip/Punch trips | G13: FABR | H13: MISC | I13: Labor | J13: San Jose | K13: ALLMODU - Allmodular Systems, Inc. | L13: 1 | M13: 0 | N13: 960 | O13: Marlene Dyson | P13: =VLOOKUP(Table1[[#This Row],[Line Item Text Code]],$U$3:$V$7,2,FALSE) -> Miscellaneous | Q13: =Table1[[#This Row],[Ext. Cost]]-Table1[[#This Row],[Ext. Sell]] -> 960 | R13: =VLOOKUP(C13,Bookings!$A$1:$B$33,2,FALSE) -> 3879926.5 | S13: =IFERROR(VLOOKUP(D13,Bookings!E:F,2,FALSE),0) -> 435136.95 | T13: =IFERROR(VLOOKUP(Table1[[#This Row],[Order]],Bookings_with_AM_Report!A:L,12,FALSE),"N/A") -> Megan Ewers
A14: 80677 | B14: 170 | C14: Lela Huenergardt | D14: Peninsula Health Care District | E14: Workrite | F14: Workrite off set credit received ? | G14: PRO | H14: VEN | I14: Vendor sent a credit out of the blue. MD | J14: San Jose | K14: WRT - Workrite Ergonomics, LLC | L14: 1 | M14: 0 | N14: 128.49 | O14: Marlene Dyson | P14: =VLOOKUP(Table1[[#This Row],[Line Item Text Code]],$U$3:$V$7,2,FALSE) -> Vendor Caused | Q14: =Table1[[#This Row],[Ext. Cost]]-Table1[[#This Row],[Ext. Sell]] -> 128.49 | R14: =VLOOKUP(C14,Bookings!$A$1:$B$33,2,FALSE) -> 3879926.5 | S14: =IFERROR(VLOOKUP(D14,Bookings!E:F,2,FALSE),0) -> 0 | T14: =IFERROR(VLOOKUP(Table1[[#This Row],[Order]],Bookings_with_AM_Report!A:L,12,FALSE),"N/A") -> N/A
A15: 81432 | B15: 23 | C15: Lela Huenergardt | D15: County of Santa Clara | E15: WAREHOUSE STORAGE | F15: Storage Dates: 01/04/25 to 02/03/25 Order: KBMH228301 - Saint Louise Regional Hospital - Pharmacy *QTE* PO# 81432-90107 Receiving# KBMH228301.05 (1) Pallet Positions Date Received:12/05/2024 Customer PO #: 81432-90107 Manufacturer: Workrite Product PO#: 81432-90106 Product Received: (3) Height Adj Bases | G15: STORE | H15: CUST | I15: Lela working with client on storage. | J15: San Jose | K15: JEISANJ - JEI | L15: 1 | M15: 0 | N15: 38 | O15: Marlene Dyson | P15: =VLOOKUP(Table1[[#This Row],[Line Item Text Code]],$U$3:$V$7,2,FALSE) -> Customer Accomodation | Q15: =Table1[[#This Row],[Ext. Cost]]-Table1[[#This Row],[Ext. Sell]] -> 38 | R15: =VLOOKUP(C15,Bookings!$A$1:$B$33,2,FALSE) -> 3879926.5 | S15: =IFERROR(VLOOKUP(D15,Bookings!E:F,2,FALSE),0) -> 435136.95 | T15: =IFERROR(VLOOKUP(Table1[[#This Row],[Order]],Bookings_with_AM_Report!A:L,12,FALSE),"N/A") -> Megan Ewers
A16: 81432 | B16: 24 | C16: Lela Huenergardt | D16: County of Santa Clara | E16: WAREHOUSE STORAGE | F16: Storage Dates: 1/12/25 - 2/11/25 Order: KBMH228301 - Saint Louise Regional Hospital - Pharmacy *QTE* PO# 81432-90107 Receiving# KBMH228301.01 (1) Pallet Positions Date Received:11/11/2024 Customer PO #: 81432-90107 Manufacturer: Grainger Product PO#: 81432-90102 Product Received: (1) Utility Cart Receiving# KBMH228301.02 (1) Carton Date Received:11/12/2024 Customer PO #: 81432-90107 Manufacturer: Grainger Product PO#: 81432-90102 Product Received: (2) Stools Receiving# KBMH228301.03 (1) Pallet Positions Date Received:11/12/2024 Customer PO #: 81432-90107 Manufacturer: Grainger Product PO#: 81432-90102 Product Received: (1) Lateral File | G16: STORE | H16: MISC | I16: Storage | J16: San Jose | K16: JEISANJ - JEI | L16: 1 | M16: 0 | N16: 91 | O16: Marlene Dyson | P16: =VLOOKUP(Table1[[#This Row],[Line Item Text Code]],$U$3:$V$7,2,FALSE) -> Miscellaneous | Q16: =Table1[[#This Row],[Ext. Cost]]-Table1[[#This Row],[Ext. Sell]] -> 91 | R16: =VLOOKUP(C16,Bookings!$A$1:$B$33,2,FALSE) -> 3879926.5 | S16: =IFERROR(VLOOKUP(D16,Bookings!E:F,2,FALSE),0) -> 435136.95 | T16: =IFERROR(VLOOKUP(Table1[[#This Row],[Order]],Bookings_with_AM_Report!A:L,12,FALSE),"N/A") -> Megan Ewers
A17: 81432 | B17: 25 | C17: Lela Huenergardt | D17: County of Santa Clara | E17: WAREHOUSE STORAGE | F17: Storage Dates: 1/20/24 to 02/19/25 Order: KBMH228301 - Saint Louise Regional Hospital - Pharmacy *QTE* PO# 81432-90107 Receiving# KBMH228301.04 (1) Pallet Positions Date Received:11/20/2024 Customer PO #: 81432-90107 Manufacturer: Eagle Group Product PO#: 81432-90102 Product Received: (2) Gowning Bench $36.00 | G17: STORE | H17: MISC | I17: Storage | J17: San Jose | K17: JEISANJ - JEI | L17: 1 | M17: 0 | N17: 38 | O17: Marlene Dyson | P17: =VLOOKUP(Table1[[#This Row],[Line Item Text Code]],$U$3:$V$7,2,FALSE) -> Miscellaneous | Q17: =Table1[[#This Row],[Ext. Cost]]-Table1[[#This Row],[Ext. Sell]] -> 38 | R17: =VLOOKUP(C17,Bookings!$A$1:$B$33,2,FALSE) -> 3879926.5 | S17: =IFERROR(VLOOKUP(D17,Bookings!E:F,2,FALSE),0) -> 435136.95 | T17: =IFERROR(VLOOKUP(Table1[[#This Row],[Order]],Bookings_with_AM_Report!A:L,12,FALSE),"N/A") -> Megan Ewers
A18: 81432 | B18: 26 | C18: Lela Huenergardt | D18: County of Santa Clara | E18: WAREHOUSE STORAGE | F18: Storage Dates: 01/25/25 to 02/24/25 Order: KBMH228301 - Saint Louise Regional Hospital - Pharmacy *QTE* PO# 81432-90107 Receiving# KBMH228301.06 (2) Pieces Date Received:12/26/2024 Customer PO #: 81432-90107 Manufacturer: Knoll Product PO#: 81432-90103 Product Received: (2) Rectangular Tops | G18: STORE | H18: MISC | I18: Storage | J18: San Jose | K18: JEISANJ - JEI | L18: 1 | M18: 0 | N18: 15 | O18: Marlene Dyson | P18: =VLOOKUP(Table1[[#This Row],[Line Item Text Code]],$U$3:$V$7,2,FALSE) -> Miscellaneous | Q18: =Table1[[#This Row],[Ext. Cost]]-Table1[[#This Row],[Ext. Sell]] -> 15 | R18: =VLOOKUP(C18,Bookings!$A$1:$B$33,2,FALSE) -> 3879926.5 | S18: =IFERROR(VLOOKUP(D18,Bookings!E:F,2,FALSE),0) -> 435136.95 | T18: =IFERROR(VLOOKUP(Table1[[#This Row],[Order]],Bookings_with_AM_Report!A:L,12,FALSE),"N/A") -> Megan Ewers
A19: 81432 | B19: 27 | C19: Lela Huenergardt | D19: County of Santa Clara | E19: WAREHOUSE STORAGE | F19: Storage Dates: 02/04/25 - 3/3/25 Order: KBMH228301 - Saint Louise Regional Hospital - Pharmacy *QTE* PO# 81432-90107 Receiving# KBMH228301.05 (1) Pallet Positions Date Received:12/05/2024 Customer PO #: 81432-90107 Manufacturer: Workrite Product PO#: 81432-90106 Product Received: (3) Height Adj Bases | G19: STORE | H19: CUST | I19: Lela working with client on storage. | J19: San Jose | K19: JEISANJ - JEI | L19: 1 | M19: 0 | N19: 38 | O19: Marlene Dyson | P19: =VLOOKUP(Table1[[#This Row],[Line Item Text Code]],$U$3:$V$7,2,FALSE) -> Customer Accomodation | Q19: =Table1[[#This Row],[Ext. Cost]]-Table1[[#This Row],[Ext. Sell]] -> 38 | R19: =VLOOKUP(C19,Bookings!$A$1:$B$33,2,FALSE) -> 3879926.5 | S19: =IFERROR(VLOOKUP(D19,Bookings!E:F,2,FALSE),0) -> 435136.95 | T19: =IFERROR(VLOOKUP(Table1[[#This Row],[Order]],Bookings_with_AM_Report!A:L,12,FALSE),"N/A") -> Megan Ewers
... A70: 82999 | B70: 70 | C70: Simon Sheppard | D70: Tri Pointe Homes Holdings, Inc | E70: KBM-PM | F70: PROJECT MANAGER | G70: PM-TAX | H70: MISC | I70: True-Up | J70: Sacramento | K70: KBM-PM - KBM-Hogue Project Management | L70: 1 | M70: 0 | N70: 1275 | O70: Marcus Freeman | P70: =VLOOKUP(Table1[[#This Row],[Line Item Text Code]],$U$3:$V$7,2,FALSE) -> Miscellaneous | Q70: =Table1[[#This Row],[Ext. Cost]]-Table1[[#This Row],[Ext. Sell]] -> 1275 | R70: =VLOOKUP(C70,Bookings!$A$1:$B$33,2,FALSE) -> 893520.77 | S70: =IFERROR(VLOOKUP(D70,Bookings!E:F,2,FALSE),0) -> 121573.87 | T70: =IFERROR(VLOOKUP(Table1[[#This Row],[Order]],Bookings_with_AM_Report!A:L,12,FALSE),"N/A") -> N/A
A71: 83085 | B71: 9 | C71: Owen Cunningham | D71: Sequoia Capital Operations, LLC | E71: MILEAGE | G71: TRV | H71: MISC | I71: Mileage | J71: San Francisco | K71: ASTOR - Astor Ng | L71: 1 | M71: 0 | N71: 30.96 | O71: Kelly Caplan | P71: =VLOOKUP(Table1[[#This Row],[Line Item Text Code]],$U$3:$V$7,2,FALSE) -> Miscellaneous | Q71: =Table1[[#This Row],[Ext. Cost]]-Table1[[#This Row],[Ext. Sell]] -> 30.96 | R71: =VLOOKUP(C71,Bookings!$A$1:$B$33,2,FALSE) -> 13189792 | S71: =IFERROR(VLOOKUP(D71,Bookings!E:F,2,FALSE),0) -> 1874548.9 | T71: =IFERROR(VLOOKUP(Table1[[#This Row],[Order]],Bookings_with_AM_Report!A:L,12,FALSE),"N/A") -> Kimi Katsuyoshi
A72: 83085 | B72: 10 | C72: Owen Cunningham | D72: Sequoia Capital Operations, LLC | E72: MILEAGE | G72: TRV | H72: MISC | I72: Mileage | J72: San Francisco | K72: ASTOR - Astor Ng | L72: 1 | M72: 0 | N72: 18.59 | O72: Kelly Caplan | P72: =VLOOKUP(Table1[[#This Row],[Line Item Text Code]],$U$3:$V$7,2,FALSE) -> Miscellaneous | Q72: =Table1[[#This Row],[Ext. Cost]]-Table1[[#This Row],[Ext. Sell]] -> 18.59 | R72: =VLOOKUP(C72,Bookings!$A$1:$B$33,2,FALSE) -> 13189792 | S72: =IFERROR(VLOOKUP(D72,Bookings!E:F,2,FALSE),0) -> 1874548.9 | T72: =IFERROR(VLOOKUP(Table1[[#This Row],[Order]],Bookings_with_AM_Report!A:L,12,FALSE),"N/A") -> Kimi Katsuyoshi
A73: 83085 | B73: 11 | C73: Owen Cunningham | D73: Sequoia Capital Operations, LLC | E73: MILEAGE | G73: TRV | H73: MISC | I73: Mileage | J73: San Francisco | K73: ASTOR - Astor Ng | L73: 1 | M73: 0 | N73: 25.32 | O73: Kelly Caplan | P73: =VLOOKUP(Table1[[#This Row],[Line Item Text Code]],$U$3:$V$7,2,FALSE) -> Miscellaneous | Q73: =Table1[[#This Row],[Ext. Cost]]-Table1[[#This Row],[Ext. Sell]] -> 25.32 | R73: =VLOOKUP(C73,Bookings!$A$1:$B$33,2,FALSE) -> 13189792 | S73: =IFERROR(VLOOKUP(D73,Bookings!E:F,2,FALSE),0) -> 1874548.9 | T73: =IFERROR(VLOOKUP(Table1[[#This Row],[Order]],Bookings_with_AM_Report!A:L,12,FALSE),"N/A") -> Kimi Katsuyoshi
A74: 83085 | B74: 12 | C74: Owen Cunningham | D74: Sequoia Capital Operations, LLC | E74: MILEAGE | G74: TRV | H74: MISC | I74: Mileage | J74: San Francisco | K74: ASTOR - Astor Ng | L74: 1 | M74: 0 | N74: 25.74 | O74: Kelly Caplan | P74: =VLOOKUP(Table1[[#This Row],[Line Item Text Code]],$U$3:$V$7,2,FALSE) -> Miscellaneous | Q74: =Table1[[#This Row],[Ext. Cost]]-Table1[[#This Row],[Ext. Sell]] -> 25.74 | R74: =VLOOKUP(C74,Bookings!$A$1:$B$33,2,FALSE) -> 13189792 | S74: =IFERROR(VLOOKUP(D74,Bookings!E:F,2,FALSE),0) -> 1874548.9 | T74: =IFERROR(VLOOKUP(Table1[[#This Row],[Order]],Bookings_with_AM_Report!A:L,12,FALSE),"N/A") -> Kimi Katsuyoshi
A75: 83085 | B75: 13 | C75: Owen Cunningham | D75: Sequoia Capital Operations, LLC | E75: MILEAGE | G75: TRV | H75: MISC | I75: Mileage | J75: San Francisco | K75: ASTOR - Astor Ng | L75: 1 | M75: 0 | N75: 25.32 | O75: Kelly Caplan | P75: =VLOOKUP(Table1[[#This Row],[Line Item Text Code]],$U$3:$V$7,2,FALSE) -> Miscellaneous | Q75: =Table1[[#This Row],[Ext. Cost]]-Table1[[#This Row],[Ext. Sell]] -> 25.32 | R75: =VLOOKUP(C75,Bookings!$A$1:$B$33,2,FALSE) -> 13189792 | S75: =IFERROR(VLOOKUP(D75,Bookings!E:F,2,FALSE),0) -> 1874548.9 | T75: =IFERROR(VLOOKUP(Table1[[#This Row],[Order]],Bookings_with_AM_Report!A:L,12,FALSE),"N/A") -> Kimi Katsuyoshi
A76: 83085 | B76: 14 | C76: Owen Cunningham | D76: Sequoia Capital Operations, LLC | E76: MILEAGE | G76: TRV | H76: MISC | I76: Mileage | J76: San Francisco | K76: ASTOR - Astor Ng | L76: 1 | M76: 0 | N76: 6.44 | O76: Kelly Caplan | P76: =VLOOKUP(Table1[[#This Row],[Line Item Text Code]],$U$3:$V$7,2,FALSE) -> Miscellaneous | Q76: =Table1[[#This Row],[Ext. Cost]]-Table1[[#This Row],[Ext. Sell]] -> 6.44 | R76: =VLOOKUP(C76,Bookings!$A$1:$B$33,2,FALSE) -> 13189792 | S76: =IFERROR(VLOOKUP(D76,Bookings!E:F,2,FALSE),0) -> 1874548.9 | T76: =IFERROR(VLOOKUP(Table1[[#This Row],[Order]],Bookings_with_AM_Report!A:L,12,FALSE),"N/A") -> Kimi Katsuyoshi
A77: 83085 | B77: 15 | C77: Owen Cunningham | D77: Sequoia Capital Operations, LLC | E77: MILEAGE | G77: TRV | H77: MISC | I77: Mileage | J77: San Francisco | K77: ASTOR - Astor Ng | L77: 1 | M77: 0 | N77: 25.32 | O77: Kelly Caplan | P77: =VLOOKUP(Table1[[#This Row],[Line Item Text Code]],$U$3:$V$7,2,FALSE) -> Miscellaneous | Q77: =Table1[[#This Row],[Ext. Cost]]-Table1[[#This Row],[Ext. Sell]] -> 25.32 | R77: =VLOOKUP(C77,Bookings!$A$1:$B$33,2,FALSE) -> 13189792 | S77: =IFERROR(VLOOKUP(D77,Bookings!E:F,2,FALSE),0) -> 1874548.9 | T77: =IFERROR(VLOOKUP(Table1[[#This Row],[Order]],Bookings_with_AM_Report!A:L,12,FALSE),"N/A") -> Kimi Katsuyoshi
A78: 83085 | B78: 16 | C78: Owen Cunningham | D78: Sequoia Capital Operations, LLC | E78: MILEAGE | G78: TRV | H78: MISC | I78: Mileage | J78: San Francisco | K78: ASTOR - Astor Ng | L78: 1 | M78: 0 | N78: 12.66 | O78: Kelly Caplan | P78: =VLOOKUP(Table1[[#This Row],[Line Item Text Code]],$U$3:$V$7,2,FALSE) -> Miscellaneous | Q78: =Table1[[#This Row],[Ext. Cost]]-Table1[[#This Row],[Ext. Sell]] -> 12.66 | R78: =VLOOKUP(C78,Bookings!$A$1:$B$33,2,FALSE) -> 13189792 | S78: =IFERROR(VLOOKUP(D78,Bookings!E:F,2,FALSE),0) -> 1874548.9 | T78: =IFERROR(VLOOKUP(Table1[[#This Row],[Order]],Bookings_with_AM_Report!A:L,12,FALSE),"N/A") -> Kimi Katsuyoshi
A79: 83213 | B79: 11 | C79: Olivia Gorfain | D79: HGGC | E79: Labor | F79: Quote Includes • 1 Trip to Site for installers to partially KD Custom workstation and replace power box Optional/ Add-line: Will Call power box from SJ $265.00 • 1 Will Call | G79: FABR | H79: CUST | I79: Customer accomodation. | J79: San Francisco | K79: SERVICE - Service West- San Leandro | L79: 1 | M79: 0 | N79: 1035 | O79: Nicole Lentini | P79: =VLOOKUP(Table1[[#This Row],[Line Item Text Code]],$U$3:$V$7,2,FALSE) -> Customer Accomodation | Q79: =Table1[[#This Row],[Ext. Cost]]-Table1[[#This Row],[Ext. Sell]] -> 1035 | R79: =VLOOKUP(C79,Bookings!$A$1:$B$33,2,FALSE) -> 25594615 | S79: =IFERROR(VLOOKUP(D79,Bookings!E:F,2,FALSE),0) -> 4058.63 | T79: =IFERROR(VLOOKUP(Table1[[#This Row],[Order]],Bookings_with_AM_Report!A:L,12,FALSE),"N/A") -> Emily Stiller
A80: 83213 | B80: 12 | C80: Olivia Gorfain | D80: HGGC | E80: Labor | F80: Optional/ Add-line: Will Call power box from SJ • 1 Will Call | G80: FABR | H80: CUST | I80: Customer accomodation. | J80: San Francisco | K80: SERVICE - Service West- San Leandro | L80: 1 | M80: 0 | N80: 265 | O80: Nicole Lentini | P80: =VLOOKUP(Table1[[#This Row],[Line Item Text Code]],$U$3:$V$7,2,FALSE) -> Customer Accomodation | Q80: =Table1[[#This Row],[Ext. Cost]]-Table1[[#This Row],[Ext. Sell]] -> 265 | R80: =VLOOKUP(C80,Bookings!$A$1:$B$33,2,FALSE) -> 25594615 | S80: =IFERROR(VLOOKUP(D80,Bookings!E:F,2,FALSE),0) -> 4058.63 | T80: =IFERROR(VLOOKUP(Table1[[#This Row],[Order]],Bookings_with_AM_Report!A:L,12,FALSE),"N/A") -> Emily Stiller
A81: 83289 | B81: 12 | C81: Alex Blangeres | D81: Placer County | E81: FREIGHT | F81: Manufacturer Shipping for Custom Mobile Island and Top | G81: PM-TAX | H81: MISC | I81: 3/7/24 PM Time original for Will Call, Order requires added Labor order. MF | J81: Sacramento | K81: KBM-PM - KBM-Hogue Project Management | L81: 1 | M81: 0 | N81: 450 | O81: Marcus Freeman | P81: =VLOOKUP(Table1[[#This Row],[Line Item Text Code]],$U$3:$V$7,2,FALSE) -> Miscellaneous | Q81: =Table1[[#This Row],[Ext. Cost]]-Table1[[#This Row],[Ext. Sell]] -> 450 | R81: =VLOOKUP(C81,Bookings!$A$1:$B$33,2,FALSE) -> 3992449.5 | S81: =IFERROR(VLOOKUP(D81,Bookings!E:F,2,FALSE),0) -> 55745.45 | T81: =IFERROR(VLOOKUP(Table1[[#This Row],[Order]],Bookings_with_AM_Report!A:L,12,FALSE),"N/A") -> N/A
A82: 83464 | B82: 111 | C82: Norma Lopez | D82: Intuit-OR 205 | E82: JPR-MCP- 0128-00 | F82: JPR-MCP-0128-00 THIN TASK - NUT FOR GROMMET | G82: PRO | H82: VEN | I82: Unknown who lost parts/where parts are located | J82: San Jose | K82: JUNIPER - Juniper Design | L82: 2 | M82: 0 | N82: 10 | O82: Julia Torres | P82: =VLOOKUP(Table1[[#This Row],[Line Item Text Code]],$U$3:$V$7,2,FALSE) -> Vendor Caused | Q82: =Table1[[#This Row],[Ext. Cost]]-Table1[[#This Row],[Ext. Sell]] -> 10 | R82: =VLOOKUP(C82,Bookings!$A$1:$B$33,2,FALSE) -> 7904036.3 | S82: =IFERROR(VLOOKUP(D82,Bookings!E:F,2,FALSE),0) -> 6485933.8 | T82: =IFERROR(VLOOKUP(Table1[[#This Row],[Order]],Bookings_with_AM_Report!A:L,12,FALSE),"N/A") -> Carina Collison
A83: 83464 | B83: 112 | C83: Norma Lopez | D83: Intuit-OR 205 | E83: JPR-PWR- 0105 | F83: 24VDC, 2A POWER SUPPLY, 90-264VAC INPUT, 1.5M BLACK BRAIDED CORD, 2.1X5.5MM MALE DC JACK, GLOSSY BLACK COVER JUNIPER LOGO, UL LISTED, INTERCHANGEABLE INTERNATIONAL PINS | G83: PRO | H83: VEN | I83: Unknown who lost parts/where parts are located | J83: San Jose | K83: JUNIPER - Juniper Design | L83: 2 | M83: 0 | N83: 50 | O83: Julia Torres | P83: =VLOOKUP(Table1[[#This Row],[Line Item Text Code]],$U$3:$V$7,2,FALSE) -> Vendor Caused | Q83: =Table1[[#This Row],[Ext. Cost]]-Table1[[#This Row],[Ext. Sell]] -> 50 | R83: =VLOOKUP(C83,Bookings!$A$1:$B$33,2,FALSE) -> 7904036.3 | S83: =IFERROR(VLOOKUP(D83,Bookings!E:F,2,FALSE),0) -> 6485933.8 | T83: =IFERROR(VLOOKUP(Table1[[#This Row],[Order]],Bookings_with_AM_Report!A:L,12,FALSE),"N/A") -> Carina Collison
A84: 83464 | B84: 113 | C84: Norma Lopez | D84: Intuit-OR 205 | E84: CBL-0009 | F84: JUMPER CABLE 2.1MM MALE TO 2.1MM MALE - 18" LENGTH, 22AWG, BLACK | G84: PRO | H84: VEN | I84: Unknown who lost parts/where parts are located | J84: San Jose | K84: JUNIPER - Juniper Design | L84: 2 | M84: 0 | N84: 10 | O84: Julia Torres | P84: =VLOOKUP(Table1[[#This Row],[Line Item Text Code]],$U$3:$V$7,2,FALSE) -> Vendor Caused | Q84: =Table1[[#This Row],[Ext. Cost]]-Table1[[#This Row],[Ext. Sell]] -> 10 | R84: =VLOOKUP(C84,Bookings!$A$1:$B$33,2,FALSE) -> 7904036.3 | S84: =IFERROR(VLOOKUP(D84,Bookings!E:F,2,FALSE),0) -> 6485933.8 | T84: =IFERROR(VLOOKUP(Table1[[#This Row],[Order]],Bookings_with_AM_Report!A:L,12,FALSE),"N/A") -> Carina Collison
A85: 83464 | B85: 114 | C85: Norma Lopez | D85: Intuit-OR 205 | E85: Delivery_011 | F85: UPS Ground | G85: SHIP | H85: VEN | I85: Unknown who lost parts/where parts are located | J85: San Jose | K85: JUNIPER - Juniper Design | L85: 1 | M85: 0 | N85: 25 | O85: Julia Torres | P85: =VLOOKUP(Table1[[#This Row],[Line Item Text Code]],$U$3:$V$7,2,FALSE) -> Vendor Caused | Q85: =Table1[[#This Row],[Ext. Cost]]-Table1[[#This Row],[Ext. Sell]] -> 25 | R85: =VLOOKUP(C85,Bookings!$A$1:$B$33,2,FALSE) -> 7904036.3 | S85: =IFERROR(VLOOKUP(D85,Bookings!E:F,2,FALSE),0) -> 6485933.8 | T85: =IFERROR(VLOOKUP(Table1[[#This Row],[Order]],Bookings_with_AM_Report!A:L,12,FALSE),"N/A") -> Carina Collison
A86: 83464 | B86: 115 | C86: Norma Lopez | D86: Intuit-OR 205 | E86: FABRICATION | F86: Labor for return trip to install (1) missing power for Library table on floor 11 | G86: FABR | H86: VEN | I86: Battery power and cable went missing when we transitioned labor companies | J86: San Jose | K86: OFFICES06 - Office System Installation | L86: 1 | M86: 0 | N86: 225 | O86: Julia Torres | P86: =VLOOKUP(Table1[[#This Row],[Line Item Text Code]],$U$3:$V$7,2,FALSE) -> Vendor Caused | Q86: =Table1[[#This Row],[Ext. Cost]]-Table1[[#This Row],[Ext. Sell]] -> 225 | R86: =VLOOKUP(C86,Bookings!$A$1:$B$33,2,FALSE) -> 7904036.3 | S86: =IFERROR(VLOOKUP(D86,Bookings!E:F,2,FALSE),0) -> 6485933.8 | T86: =IFERROR(VLOOKUP(Table1[[#This Row],[Order]],Bookings_with_AM_Report!A:L,12,FALSE),"N/A") -> Carina Collison
A87: 83563 | B87: 15 | C87: Troy Ocariza | D87: East Side Union High School District | E87: LABOR | F87: SM Non-Union Installation and testing of soundmasking system, during Normal Business Hours. Includes Lift equipment. | G87: FABR | H87: MISC | I87: scissor lift not used | J87: San Jose | K87: MPSLLC - MPSLLC | L87: 1 | M87: 0 | N87: -1500 | O87: Angela Farmer | P87: =VLOOKUP(Table1[[#This Row],[Line Item Text Code]],$U$3:$V$7,2,FALSE) -> Miscellaneous | Q87: =Table1[[#This Row],[Ext. Cost]]-Table1[[#This Row],[Ext. Sell]] -> -1500 | R87: =VLOOKUP(C87,Bookings!$A$1:$B$33,2,FALSE) -> 927982.08 | S87: =IFERROR(VLOOKUP(D87,Bookings!E:F,2,FALSE),0) -> 255103.65 | T87: =IFERROR(VLOOKUP(Table1[[#This Row],[Order]],Bookings_with_AM_Report!A:L,12,FALSE),"N/A") -> Troy Ocariza
A88: 83906 | B88: 31 | C88: Jill Marsh | D88: Charles Schwab | E88: Ariba Fees | F88: January | G88: FEE | H88: VEN | I88: Ariba SAP Fees | J88: San Francisco | K88: ARIBAIN - Ariba, Inc. | L88: 1 | M88: 0 | N88: 107.69 | O88: Nicole Lentini | P88: =VLOOKUP(Table1[[#This Row],[Line Item Text Code]],$U$3:$V$7,2,FALSE) -> Vendor Caused | Q88: =Table1[[#This Row],[Ext. Cost]]-Table1[[#This Row],[Ext. Sell]] -> 107.69 | R88: =VLOOKUP(C88,Bookings!$A$1:$B$33,2,FALSE) -> 6210075.2 | S88: =IFERROR(VLOOKUP(D88,Bookings!E:F,2,FALSE),0) -> 214888.15 | T88: =IFERROR(VLOOKUP(Table1[[#This Row],[Order]],Bookings_with_AM_Report!A:L,12,FALSE),"N/A") -> Paul Razo
A89: 84117 | B89: 52 | C89: Shayle Wallis | D89: Walter's House | E89: RETURN TRIP | F89: CIW - return trip charges | G89: FABR | H89: MISC | I89: Labor | J89: Sacramento | K89: COMMERC04 - Commercial Interiors West, Inc. | L89: 1 | M89: 0 | N89: 480 | O89: Marlene Dyson | P89: =VLOOKUP(Table1[[#This Row],[Line Item Text Code]],$U$3:$V$7,2,FALSE) -> Miscellaneous | Q89: =Table1[[#This Row],[Ext. Cost]]-Table1[[#This Row],[Ext. Sell]] -> 480 | R89: =VLOOKUP(C89,Bookings!$A$1:$B$33,2,FALSE) -> 2269779.3 | S89: =IFERROR(VLOOKUP(D89,Bookings!E:F,2,FALSE),0) -> 89212.4 | T89: =IFERROR(VLOOKUP(Table1[[#This Row],[Order]],Bookings_with_AM_Report!A:L,12,FALSE),"N/A") -> Erika Duarte
A90: 84117 | B90: 53 | C90: Shayle Wallis | D90: Walter's House | E90: DESIGN SERVICES | F90: KBM Hogue Design Services | G90: DSGN | H90: SPEC | I90: Additional Design hours. The sell is on the order 89460 | J90: Sacramento | K90: KBM-DESIGN - KBM-Hogue Design | L90: 43.3333 | M90: 0 | N90: 3250 | O90: Marlene Dyson | P90: =VLOOKUP(Table1[[#This Row],[Line Item Text Code]],$U$3:$V$7,2,FALSE) -> Specification Error | Q90: =Table1[[#This Row],[Ext. Cost]]-Table1[[#This Row],[Ext. Sell]] -> 3250 | R90: =VLOOKUP(C90,Bookings!$A$1:$B$33,2,FALSE) -> 2269779.3 | S90: =IFERROR(VLOOKUP(D90,Bookings!E:F,2,FALSE),0) -> 89212.4 | T90: =IFERROR(VLOOKUP(Table1[[#This Row],[Order]],Bookings_with_AM_Report!A:L,12,FALSE),"N/A") -> Erika Duarte
...

Sheet Bookings
A1: Salesperson | B1: Sum of Total Sell | E1: Client | F1: Sum of Total Sell | I1: AM | J1: Sum of Total Sell
A2: Alex Blangeres | B2: 3992449.5 | E2: 201 Spear Property, LLC | F2: 291498.43 | J2: 151844.66
A3: Anthony Pantaleoni | B3: 325857.38 | E3: 345 California L.P. | F3: 6786 | I3: Alex Blangeres | J3: 0
A4: Chris Cicisly | B4: 6995960.2 | E4: 6Sense | F4: 77925 | I4: Andrea Greever | J4: 501309.46
A5: Erika Duarte | B5: 3309.31 | E5: 84 West LLC | F5: 79008.91 | I5: Anthony Pantaleoni | J5: 11090765
A6: Farrah Race | B6: 17764.57 | E6: AAA Northern California, Utah & Nevada | F6: 1690928.3 | I6: Anthony Pantaleoni,Hana Estrada | J6: 189553.69
A7: Genesis Rita | B7: 1079.55 | E7: ABC10 | F7: 424.02 | I7: Anthony Pantaleoni,Josie Maitlen | J7: 0
A8: Jenni Lombardi | B8: 3917134.9 | E8: Accel Management Co | F8: 106367 | I8: Anthony Pantaleoni,Melissa Rokes | J8: 846951.72
A9: Jill Marsh | B9: 6210075.2 | E9: Acosta & Sons Inc | F9: 923.07 | I9: Anthony Pantaleoni,Torrey Crell | J9: 1325
A10: Kate Ingelstrom | B10: 2600398.1 | E10: Adrian Wall | F10: 799.5 | I10: Carina Collison | J10: 2139565
A11: Kimi Katsuyoshi | B11: 17992.6 | E11: AdVal Properties | F11: 11392.64 | I11: Casey Fleming | J11: 501061.62
A12: Lela Huenergardt | B12: 3879926.5 | E12: Adventist | F12: 0 | I12: Casey Fleming,Norma Lopez | J12: 66593.24
A13: Lindsay Hanief | B13: 11238.25 | E13: Aedis Architecture | F13: 0 | I13: Casey Fleming,Troy Ocariza | J13: 0
A14: Mark Dailey | B14: 1917863.2 | E14: Affordable Interior Systems | F14: 450 | I14: Chris Cicisly | J14: 4973.24
... A37: Grand Total | B37: 84735438 | E37: Bay Area Headquarters Authority | F37: 339398.68 | I37: Hana Estrada,Melissa Rokes,Torrey Crell | J37: 0
E38: Be Workplace Design | F38: 22827.78 | I38: Hana Estrada,Paul Razo | J38: 183647.18
E39: Berkeley Endowment Management Company | F39: 10780 | I39: Hana Estrada,Torrey Crell | J39: 5939.76
E40: Berkeley Research Group, LLC | F40: 9499.6 | I40: Jenni Lombardi | J40: 6601711.8
E41: Best, Best & Krieger LLP | F41: 6246.15 | I41: Jessica Ramirez | J41: 1853042.4
E42: BioMed Realty | F42: 0 | I42: Jillian Galla | J42: 206957.95
E43: bioMerieux | F43: 0 | I43: Josie Maitlen | J43: 1141056.4
E44: Blue Bottle Coffee | F44: 38549.33 | I44: Josie Maitlen,Melissa Rokes | J44: 25249.83
E45: Boston Properties | F45: 0 | I45: Josie Maitlen,Torrey Crell | J45: 5075193.4
E46: Boston Properties Limited Partnership | F46: 591585.21 | I46: Kate Ingelstrom | J46: 817.81
E47: Boutin Jones, Inc. | F47: 11026.59 | I47: Kimi Katsuyoshi | J47: 1135782.4
E48: Brandy Dunkel | F48: 338.16 | I48: Kimi Katsuyoshi,Melissa Avalos | J48: 1047400.2
E49: BridgeBio Pharma, Inc | F49: 660 | I49: Kimi Katsuyoshi,Saoirse O'Connor | J49: 658
... E105: Crowdstrike | F105: 22810.07 | I105: Grand Total | J105: 84735438
E106: Crunchyroll LLC | F106: 91858
E107: Cushman & Wakefield | F107: 40007
E108: CVC Advisors (U.S.), Inc | F108: 1050
E109: Cytokinetics | F109: 2174302
E110: DataRobot | F110: 0
E111: DataSpan Holdings, Inc | F111: 0
E112: Dauphin | F112: 190
E113: David Gensler | F113: 1167.75
E114: Davis Polk & Wardwell LLP | F114: 670595.27
E115: Debner, Inc | F115: 725
E116: Deep Origin | F116: 44523.75
E117: Defense Contract Management Agency | F117: 3309.31
...

Sheet Bookings_with_AM_Report
A1: Order # | B1: Activity Date | C1: Customer | D1: Salesperson | E1: Company | F1: New Sell | G1: Adj Sell | H1: Total Sell | I1: Total Cost | J1: GP | K1: GP % | L1: Account Manager
A2: 88802 | B2: 45659 | C2: Hines West LLC | D2: Anthony Pantaleoni | E2: San Francisco | F2: 0 | G2: 0 | H2: 0 | I2: -102 | J2: 102 | K2: 0 | L2: Anthony Pantaleoni,Hana Estrada
A3: 82661 | B3: 45659 | C3: WelbeHealth, LLC | D3: Alex Blangeres | E3: Sacramento | F3: 0 | G3: 0 | H3: 0 | I3: 523.45 | J3: -523.45 | K3: 0 | L3: Farrah Race
A4: 85709 | B4: 45659 | C4: WelbeHealth, LLC | D4: Alex Blangeres | E4: Sacramento | F4: 0 | G4: 0 | H4: 0 | I4: 66.99 | J4: -66.99 | K4: 0 | L4: Farrah Race
A5: 85928 | B5: 45659 | C5: E-Commerce Orders | D5: Norma Lopez | E5: San Jose | F5: 0 | G5: 0 | H5: 0 | I5: 18.77 | J5: -18.77 | K5: 0 | L5: Norma Lopez
A6: 86929 | B6: 45659 | C6: Littler Mendelson, P.C. | D6: Kate Ingelstrom | E6: San Jose | F6: 0 | G6: 378.38 | H6: 378.38 | I6: 280 | J6: 98.38 | K6: 0.26000317 | L6: Genesis Rita
A7: 87688 | B7: 45659 | C7: AAA Northern California, Utah & Nevada | D7: Mark Dailey | E7: Sacramento | F7: 0 | G7: 0 | H7: 0 | I7: 483.43 | J7: -483.43 | K7: 0 | L7: Rayna Mitchell
A8: 87690 | B8: 45659 | C8: AAA Northern California, Utah & Nevada | D8: Mark Dailey | E8: Sacramento | F8: 0 | G8: 0 | H8: 0 | I8: 42.01 | J8: -42.01 | K8: 0 | L8: Rayna Mitchell
A9: 87808 | B9: 45659 | C9: Intuit-OR 205 | D9: Norma Lopez | E9: San Jose | F9: 0 | G9: 0 | H9: 0 | I9: 526.2 | J9: -526.2 | K9: 0 | L9: Jessica Ramirez
A10: 88845 | B10: 45659 | C10: Stanford University | D10: Jill Marsh | E10: San Francisco | F10: 0 | G10: 0 | H10: 0 | I10: 25.7 | J10: -25.7 | K10: 0 | L10: Lindsay Hanief
A11: 88871 | B11: 45659 | C11: Intuit-OR 205 | D11: Norma Lopez | E11: San Jose | F11: 0 | G11: 0 | H11: 0 | I11: 674.7 | J11: -674.7 | K11: 0 | L11: Jessica Ramirez
A12: 89045 | B12: 45659 | C12: Qatalyst Partners LP | D12: Chris Cicisly | E12: San Jose | F12: 0 | G12: 0 | H12: 0 | I12: 0 | J12: 0 | K12: 0 | L12: Mary Sparacino
A13: 89416 | B13: 45659 | C13: Best, Best & Krieger LLP | D13: Troy Ocariza | E13: San Jose | F13: 0 | G13: 0 | H13: 0 | I13: -131.77 | J13: 131.77 | K13: 0 | L13: Troy Ocariza
... A6633: 93476 | B6633: 45863 | C6633: Littler Mendelson, P.C. | D6633: Kate Ingelstrom | E6633: San Jose | F6633: 0 | G6633: 48.5 | H6633: 48.5 | I6633: 36.86 | J6633: 11.64 | K6633: 0.24 | L6633: Genesis Rita
A6634: 93572 | B6634: 45863 | C6634: Owen Cunningham | D6634: Matt Denning | E6634: San Francisco | F6634: 950 | G6634: 0 | H6634: 950 | I6634: 950 | J6634: 0 | K6634: 0
A6635: 93654 | B6635: 45863 | C6635: Wilson Sonsini Goodrich & Rosati | D6635: Jenni Lombardi | E6635: San Jose | F6635: 3750 | G6635: 0 | H6635: 3750 | I6635: 0 | J6635: 3750 | K6635: 1 | L6635: Jenni Lombardi
A6636: 93656 | B6636: 45863 | C6636: Wilson Sonsini Goodrich & Rosati | D6636: Jenni Lombardi | E6636: San Jose | F6636: 200 | G6636: 0 | H6636: 200 | I6636: 0 | J6636: 200 | K6636: 1 | L6636: Jenni Lombardi
A6637: 93657 | B6637: 45863 | C6637: Wilson Sonsini Goodrich & Rosati | D6637: Jenni Lombardi | E6637: San Jose | F6637: 3025 | G6637: 0 | H6637: 3025 | I6637: 0 | J6637: 3025 | K6637: 1 | L6637: Jenni Lombardi
A6638: 93658 | B6638: 45863 | C6638: Wilson Sonsini Goodrich & Rosati | D6638: Jenni Lombardi | E6638: San Jose | F6638: 900 | G6638: 0 | H6638: 900 | I6638: 0 | J6638: 900 | K6638: 1 | L6638: Jenni Lombardi
A6639: 93659 | B6639: 45863 | C6639: Wilson Sonsini Goodrich & Rosati | D6639: Jenni Lombardi | E6639: San Jose | F6639: 200 | G6639: 0 | H6639: 200 | I6639: 0 | J6639: 200 | K6639: 1 | L6639: Jenni Lombardi
A6640: 93660 | B6640: 45863 | C6640: Wilson Sonsini Goodrich & Rosati | D6640: Jenni Lombardi | E6640: San Jose | F6640: 25 | G6640: 0 | H6640: 25 | I6640: 0 | J6640: 25 | K6640: 1 | L6640: Jenni Lombardi
A6641: 93673 | B6641: 45863 | C6641: Levi Strauss & Co | D6641: Owen Cunningham | E6641: San Francisco | F6641: 751 | G6641: 0 | H6641: 751 | I6641: 751 | J6641: 0 | K6641: 0 | L6641: Josie Maitlen,Torrey Carroll
A6642: 93676 | B6642: 45863 | C6642: Wilson Sonsini Goodrich & Rosati | D6642: Jenni Lombardi | E6642: San Jose | F6642: 1370.62 | G6642: 0 | H6642: 1370.62 | I6642: 1165 | J6642: 205.62 | K6642: 0.1500197 | L6642: Jenni Lombardi
A6643: 93688 | B6643: 45863 | C6643: Intuit-OR 205 | D6643: Norma Lopez | E6643: San Jose | F6643: 3854.46 | G6643: 0 | H6643: 3854.46 | I6643: 2939.03 | J6643: 915.43 | K6643: 0.2374989 | L6643: Norma Lopez
A6644: 93713 | B6644: 45863 | C6644: Intuit-OR 205 | D6644: Norma Lopez | E6644: San Jose | F6644: 31595.83 | G6644: 0 | H6644: 31595.83 | I6644: 21607.5 | J6644: 9988.33 | K6644: 0.31612811 | L6644: Jessica Ramirez
A6645: 93740 | B6645: 45863 | C6645: Wilson Sonsini Goodrich & Rosati | D6645: Jenni Lombardi | E6645: San Jose | F6645: 5004.96 | G6645: 0 | H6645: 5004.96 | I6645: 4254.22 | J6645: 750.74 | K6645: 0.1499992 | L6645: Jenni Lombardi
A6646: 93742 | B6646: 45863 | C6646: Wilson Sonsini Goodrich & Rosati | D6646: Jenni Lombardi | E6646: San Jose | F6646: 6120.08 | G6646: 0 | H6646: 6120.08 | I6646: 5202.07 | J6646: 918.01 | K6646: 0.14999967 | L6646: Jenni Lombardi
... A6652: 93537 | B6652: 45866 | C6652: Chan Zuckerberg Initiative | D6652: Owen Cunningham | E6652: San Francisco | F6652: 0 | G6652: 0 | H6652: 0 | I6652: 841.53 | J6652: -841.53 | K6652: 0 | L6652: Frances Kim,Kimi Katsuyoshi
A6653: 93572 | B6653: 45866 | C6653: Owen Cunningham | D6653: Matt Denning | E6653: San Francisco | F6653: 1900 | G6653: 0 | H6653: 1900 | I6653: 1900 | J6653: 0 | K6653: 0
A6654: 86211 | B6654: 45866 | C6654: Shorenstein | D6654: Jill Marsh | E6654: San Francisco | F6654: 0 | G6654: 3584.03 | H6654: 3584.03 | I6654: 3069.36 | J6654: 514.67 | K6654: 0.14360092 | L6654: Paul Razo
A6655: 86702 | B6655: 45866 | C6655: Charles Schwab | D6655: Jill Marsh | E6655: San Francisco | F6655: 0 | G6655: -2306.58 | H6655: -2306.58 | I6655: 0 | J6655: -2306.58 | K6655: 1 | L6655: Paul Razo
A6656: 87104 | B6656: 45866 | C6656: Third District Court of Appeal | D6656: Alex Blangeres | E6656: Sacramento | F6656: 0 | G6656: 0 | H6656: 0 | I6656: -150 | J6656: 150 | K6656: 0 | L6656: Farrah Race
A6657: 88772 | B6657: 45866 | C6657: Patient Square Capital | D6657: Owen Cunningham | E6657: San Francisco | F6657: 0 | G6657: 2100 | H6657: 2100 | I6657: 1503.81 | J6657: 596.19 | K6657: 0.2839 | L6657: Kimi Katsuyoshi
A6658: 89645 | B6658: 45866 | C6658: Boston Properties Limited Partnership | D6658: Olivia Gorfain | E6658: San Francisco | F6658: 5472.12 | G6658: 0 | H6658: 5472.12 | I6658: 4651.3 | J6658: 820.82 | K6658: 0.15000037 | L6658: Josie Maitlen
A6659: 90206 | B6659: 45866 | C6659: AAA Northern California, Utah & Nevada | D6659: Mark Dailey | E6659: Sacramento | F6659: 0 | G6659: 0 | H6659: 0 | I6659: -1768.75 | J6659: 1768.75 | K6659: 0 | L6659: Rayna Mitchell
A6660: 90212 | B6660: 45866 | C6660: Longfellow Real Estate Partners LLC | D6660: Anthony Pantaleoni | E6660: San Francisco | F6660: 5056.09 | G6660: 0 | H6660: 5056.09 | I6660: 5196.25 | J6660: -140.16 | K6660: -0.02772103 | L6660: Anthony Pantaleoni,Melissa Rokes
A6661: 90472 | B6661: 45866 | C6661: County of Santa Clara | D6661: Lela Huenergardt | E6661: San Jose | F6661: 0 | G6661: 0 | H6661: 0 | I6661: 223.42 | J6661: -223.42 | K6661: 0 | L6661: Megan Ewers
A6662: 90822 | B6662: 45866 | C6662: Dodge and Cox | D6662: Jill Marsh | E6662: San Francisco | F6662: 0 | G6662: 1315 | H6662: 1315 | I6662: 917.28 | J6662: 397.72 | K6662: 0.30244867 | L6662: Frances Kim
A6663: 90891 | B6663: 45866 | C6663: Judicial Council of California | D6663: Alex Blangeres | E6663: Sacramento | F6663: 0 | G6663: 0 | H6663: 0 | I6663: -76.55 | J6663: 76.55 | K6663: 0 | L6663: Rayna Mitchell
A6664: 91126 | B6664: 45866 | C6664: Simpson Thacher & Bartlett LLP | D6664: Olivia Gorfain | E6664: San Francisco | F6664: 0 | G6664: -1802423.3 | H6664: -1802423.3 | I6664: 0 | J6664: -1802423.3 | K6664: 1 | L6664: Anthony Pantaleoni
...
